<!doctype html>
<html class="no-js" lang="en">

<head>
  <!-- Global site tag (gtag.js) - Google Analytics -->
  <script async src="https://www.googletagmanager.com/gtag/js?id=UA-134931760-1"></script>
  <script>
    window.dataLayer = window.dataLayer || [];
    function gtag(){dataLayer.push(arguments);}
    gtag('js', new Date());

    gtag('config', 'UA-134931760-1');
  </script>

  <meta charset="utf-8">
  <meta http-equiv="x-ua-compatible" content="ie=edge">
  <title>Destructive exceptions</title>
  <link rel="icon" type="image/x-icon" href="/favicon.ico" />
  <meta name="description" content="Once again about why it is bad to throw exceptions in destructors 


 Many C ++ experts (for example, the Sutter coat of arms ) teach us that throwing...">
  <meta name="viewport" content="width=device-width, initial-scale=1, shrink-to-fit=no">

  <link rel="stylesheet" href="../../css/main.css">

  <script src="https://cdnjs.cloudflare.com/ajax/libs/jquery/3.3.1/jquery.min.js"></script>
  <script>window.jQuery || document.write('<script src="../../js/vendors/jquery-3.3.1.min.js"><\/script>')</script>

  <script async src="//pagead2.googlesyndication.com/pagead/js/adsbygoogle.js"></script>
  <script>
       (adsbygoogle = window.adsbygoogle || []).push({
            google_ad_client: "ca-pub-6974184241884155",
            enable_page_level_ads: true
       });
  </script>
</head>

<body>
  <!--[if lte IE 9]>
    <p class="browserupgrade">You are using an <strong>outdated</strong> browser. Please <a href="https://browsehappy.com/">upgrade your browser</a> to improve your experience and security.</p>
  <![endif]-->
  <header class="page-header js-page-header">
    <a class="page-header-logo-container" href="https://weekly-geekly.github.io/index.html"></a>
    <div class="page-header-text">Geekly Articles each Day</div>
  </header>
  <nav class="page-headings-container js-page-headings-container"></nav>
  <div class="tools-bar js-tools-bar">
    <!-- <a href="../../search.html" title="Search">üîé</a> -->
    <a class="js-list-of-headings-button" data-state="closed" href="#" title="Headings">üìú</a>
    <a class="js-go-to-top-button" href="#" title="Go to Top">‚¨ÜÔ∏è</a>
    <a class="js-go-to-bottom-button" href="#" title="Go to Bottom">‚¨áÔ∏è</a>
  </div>
  <a href="http://bit.ly/donateToWeeklyGeekly" class="donate-btn">DONATE</a>
  <section class="page js-page"><h1>Destructive exceptions</h1><div class="post__text post__text-html js-mediator-article"><h2 id="eschyo-raz-o-tom-pochemu-ploho-brosat-isklyucheniya-v-destruktorah">  Once again about why it is bad to throw exceptions in destructors </h2><br><p>  Many C ++ experts (for example, the <a href="https://www.ozon.ru/context/detail/id/1273200/">Sutter coat of arms</a> ) teach us that throwing exceptions in destructors is bad, because you can get into the destructor while spinning a stack with an exception already thrown, and if another exception is thrown at that moment, <em>std</em> will be called <em>:: terminate ()</em> .  The C ++ 17 language standard (hereinafter I refer to the freely available version of the <a href="http://www.open-std.org/jtc1/sc22/wg21/docs/papers/2017/n4713.pdf">N4713</a> draft) tells us the following about this topic: </p><a name="habracut"></a><br><blockquote>  <strong>18.5.1 The std :: terminate () function [except.terminate]</strong> <br><br>  1 substitution error handling techniques.  [Note: <br><br>  These situations are: 
      <br>
        <script async src="//pagead2.googlesyndication.com/pagead/js/adsbygoogle.js"></script>
        <ins class="adsbygoogle"
          style="display:block; text-align:center;"
          data-ad-layout="in-article"
          data-ad-format="fluid"
          data-ad-client="ca-pub-6974184241884155"
          data-ad-slot="8945601208"></ins>
        <script>
          (adsbygoogle = window.adsbygoogle || []).push({});
        </script>
      <br>
      ... <br><br>  (1.4) when unwinding (18.2) terminates by throwing an exception, or <br><br>  ... <br><br>  - end note] </blockquote><p>  Let's check on a simple example: </p><br><pre><code class="plaintext hljs">#include &lt;iostream&gt; class PrintInDestructor { public: ~PrintInDestructor() noexcept { std::cerr &lt;&lt; "~PrintInDestructor() invoked\n"; } }; void throw_int_func() { std::cerr &lt;&lt; "throw_int_func() invoked\n"; throw 1; } class ThrowInDestructor { public: ~ThrowInDestructor() noexcept(false) { std::cerr &lt;&lt; "~ThrowInDestructor() invoked\n"; throw_int_func(); } private: PrintInDestructor member_; }; int main(int, char**) { try { ThrowInDestructor bad; throw "BANG!"; } catch (int i) { std::cerr &lt;&lt; "Catched int exception: " &lt;&lt; i &lt;&lt; "\n"; } catch (const char* c) { std::cerr &lt;&lt; "Catched const char* exception: " &lt;&lt; c &lt;&lt; "\n"; } catch (...) { std::cerr &lt;&lt; "Catched unknown exception\n"; } return 0; }</code> </pre> <br><p>  Result: </p><br><pre> <code class="plaintext hljs">~ThrowInDestructor() invoked throw_int_func() invoked ~PrintInDestructor() invoked terminate called after throwing an instance of 'int' Aborted</code> </pre> <br><p>  Note that the <em>PrintInDestructor</em> destructor is still called, i.e.  after throwing the second exception, the stack spinup is not interrupted.  In the Standard (the same paragraph 18.5.1) on this subject the following is said: </p><br><blockquote>  2 ... In the situation where the handler is found, <br>  it is not necessary to determine whether it‚Äôs std :: terminate () is called.  In <br>  the situation for the handler (18.3) <br>  it is not-throwing exception specification (18.4), <br>  unwound partially or unwound std :: terminate () is called ... </blockquote><p>  I tested this example on several versions of <strong>GCC</strong> (8.2, 7.3) and <strong>Clang</strong> (6.0, 5.0), everywhere the stack promotion continues.  If you find a compiler where implementation-defined is different, please write about it in the comments. </p><br><p>  It should also be noted that <em>std :: terminate ()</em> is only called when promoting a stack when an exception is thrown out of the destructor.  If there is a try / catch block inside the destructor that catches an exception and does not forward further, this does not interrupt the unwinding of the outer exception stack. </p><br><pre> <code class="plaintext hljs">class ThrowCatchInDestructor { public: ~ThrowCatchInDestructor() noexcept(false) { try { throw_int_func(); } catch (int i) { std::cerr &lt;&lt; "Catched int in ~ThrowCatchInDestructor(): " &lt;&lt; i &lt;&lt; "\n"; } } private: PrintInDestructor member_; }; int main(int, char**) { try { ThrowCatchInDestructor good; std::cerr &lt;&lt; "ThrowCatchInDestructor instance created\n"; throw "BANG!"; } catch (int i) { std::cerr &lt;&lt; "Catched int exception: " &lt;&lt; i &lt;&lt; "\n"; } catch (const char* s) { std::cerr &lt;&lt; "Catched const char* exception: " &lt;&lt; s &lt;&lt; "\n"; } catch (...) { std::cerr &lt;&lt; "Catched unknown exception\n"; } return 0; }</code> </pre> <br><p>  displays </p><br><pre> <code class="plaintext hljs">ThrowCatchInDestructor instance created throw_int_func() invoked Catched int in ~ThrowCatchInDestructor(): 1 ~PrintInDestructor() invoked Catched const char* exception: BANG!</code> </pre> <br><p>  How to avoid unpleasant situations?  In theory, everything is simple: never throw exceptions to the destructor.  However, in practice it is not so easy to beautifully and elegantly implement this simple requirement. </p><br><h2 id="esli-nelzya-no-ochen-hochetsya">  If you can not, but really want ... </h2><br><blockquote>  Immediately, I‚Äôm not trying to justify throwing exceptions from the destructor, and following Sutter, Meyers and other C ++ gurus I urge you <strong>to try</strong> never to do this (at least in the new code).  However, a programmer in actual practice may well encounter a legacy code that does not easily lead to high standards.  In addition, the techniques described below can often come in handy during the debugging process. </blockquote><p>  For example, we are developing a library with a wrapper class that encapsulates working with a certain resource.  In accordance with the principles of RAII, we capture the resource in the constructor and must free it in the destructor.  But what if the attempt to free a resource ends in error?  Solutions to this problem: </p><br><ul><li>  Ignore the error.  Bad, because we hide a problem that may affect other parts of the system. </li><li>  Write to the log.  Better than just ignoring, but still bad, because  our library does not know anything about the logging policies adopted in the system that uses it.  The standard log can be redirected to / dev / null, with the result that, again, we will not see the error. </li><li>  To make the release of a resource into a separate function that returns a value or throws an exception, and force the class user to call it independently.  Bad, because the user can forget to do it at all, and we get a resource leak. </li><li>  Throw an exception.  Good in ordinary cases, because  a class user can catch an exception and in a standard way obtain information about the error that occurred.  Bad during stack promotion, because  results in <em>std :: terminate ()</em> . </li></ul><br><p>  How to understand whether we are currently in the process of promotion of the stack on the exception or not?  In C ++, there is a special function <em>std :: uncaught_exception () for this</em> .  With its help, we can safely throw an exception in a normal situation, or do something less correct, but not leading to an exception being thrown during the stack promotion. </p><br><pre> <code class="plaintext hljs">class ThrowInDestructor { public: ~ThrowInDestructor() noexcept(false) { if (std::uncaught_exception()) { std::cerr &lt;&lt; "~ThrowInDestructor() stack unwinding, not throwing\n"; } else { std::cerr &lt;&lt; "~ThrowInDestructor() normal case, throwing\n"; throw_int_func(); } } private: PrintInDestructor member_; }; int main(int, char**) { try { ThrowInDestructor normal; std::cerr &lt;&lt; "ThrowInDestructor normal destruction\n"; } catch (int i) { std::cerr &lt;&lt; "Catched int exception: " &lt;&lt; i &lt;&lt; "\n"; } try { ThrowInDestructor stack_unwind; std::cerr &lt;&lt; "ThrowInDestructor stack unwinding\n"; throw "BANG!"; } catch (int i) { std::cerr &lt;&lt; "Catched int exception: " &lt;&lt; i &lt;&lt; "\n"; } catch (const char* s) { std::cerr &lt;&lt; "Catched const char* exception: " &lt;&lt; s &lt;&lt; "\n"; } catch (...) { std::cerr &lt;&lt; "Catched unknown exception\n"; } return 0; }</code> </pre> <br><p>  Result: </p><br><pre> <code class="plaintext hljs">ThrowInDestructor normal destruction ~ThrowInDestructor() normal case, throwing throw_int_func() invoked ~PrintInDestructor() invoked Catched int exception: 1 ThrowInDestructor stack unwinding ~ThrowInDestructor() stack unwinding, not throwing ~PrintInDestructor() invoked Catched const char* exception: BANG!</code> </pre> <br><p>  Please note that the <em>std :: uncaught_exception ()</em> function is <em>deprecated</em> starting with C ++ Standard 17, therefore, in order to compile an example, the corresponding worning has to be suppressed (see the <a href="https://github.com/igor-semenov/code_samples/tree/master/destructive_exceptions">repository with examples from the article</a> ). </p><br><p>  The problem with this function is that it checks whether we are in the process of spin stack promotion by exception.  But it‚Äôs impossible to understand whether the current destructor was called during the stack promotion.  As a result, if stack promotion occurs, but the destructor of some object is called normally, <em>std :: uncaught_exception ()</em> will still return <em>true</em> . </p><br><pre> <code class="plaintext hljs">class MayThrowInDestructor { public: ~MayThrowInDestructor() noexcept(false) { if (std::uncaught_exception()) { std::cerr &lt;&lt; "~MayThrowInDestructor() stack unwinding, not throwing\n"; } else { std::cerr &lt;&lt; "~MayThrowInDestructor() normal case, throwing\n"; throw_int_func(); } } }; class ThrowCatchInDestructor { public: ~ThrowCatchInDestructor() noexcept(false) { try { MayThrowInDestructor may_throw; } catch (int i) { std::cerr &lt;&lt; "Catched int in ~ThrowCatchInDestructor(): " &lt;&lt; i &lt;&lt; "\n"; } } private: PrintInDestructor member_; }; int main(int, char**) { try { ThrowCatchInDestructor stack_unwind; std::cerr &lt;&lt; "ThrowInDestructor stack unwinding\n"; throw "BANG!"; } catch (int i) { std::cerr &lt;&lt; "Catched int exception: " &lt;&lt; i &lt;&lt; "\n"; } catch (const char* s) { std::cerr &lt;&lt; "Catched const char* exception: " &lt;&lt; s &lt;&lt; "\n"; } catch (...) { std::cerr &lt;&lt; "Catched unknown exception\n"; } return 0; }</code> </pre> <br><p>  Result: </p><br><pre> <code class="plaintext hljs">ThrowInDestructor stack unwinding ~MayThrowInDestructor() stack unwinding, not throwing ~PrintInDestructor() invoked Catched const char* exception: BANG!</code> </pre> <br><p>  In the new C ++ Standard Standard 17, <em>std :: uncaught_exception ()</em> introduced the function <em>std :: uncaught_exceptions ()</em> (pay attention to the plural), which instead of the boolean value returns the number of currently active exceptions (here is a detailed <a href="http://www.open-std.org/jtc1/sc22/wg21/docs/papers/2014/n4152.pdf">justification</a> ). </p><br><p>  Here's how the problem described above is solved with <em>std :: uncaught_exceptions ()</em> : </p><br><pre> <code class="plaintext hljs">class MayThrowInDestructor { public: MayThrowInDestructor() : exceptions_(std::uncaught_exceptions()) {} ~MayThrowInDestructor() noexcept(false) { if (std::uncaught_exceptions() &gt; exceptions_) { std::cerr &lt;&lt; "~MayThrowInDestructor() stack unwinding, not throwing\n"; } else { std::cerr &lt;&lt; "~MayThrowInDestructor() normal case, throwing\n"; throw_int_func(); } } private: int exceptions_; }; class ThrowCatchInDestructor { public: ~ThrowCatchInDestructor() noexcept(false) { try { MayThrowInDestructor may_throw; } catch (int i) { std::cerr &lt;&lt; "Catched int in ~ThrowCatchInDestructor(): " &lt;&lt; i &lt;&lt; "\n"; } } private: PrintInDestructor member_; }; int main(int, char**) { try { ThrowCatchInDestructor stack_unwind; std::cerr &lt;&lt; "ThrowInDestructor stack unwinding\n"; throw "BANG!"; } catch (int i) { std::cerr &lt;&lt; "Catched int exception: " &lt;&lt; i &lt;&lt; "\n"; } catch (const char* s) { std::cerr &lt;&lt; "Catched const char* exception: " &lt;&lt; s &lt;&lt; "\n"; } catch (...) { std::cerr &lt;&lt; "Catched unknown exception\n"; } return 0; }</code> </pre> <br><p>  Result: </p><br><pre> <code class="plaintext hljs">ThrowInDestructor stack unwinding ~MayThrowInDestructor() normal case, throwing throw_int_func() invoked Catched int in ~ThrowCatchInDestructor(): 1 ~PrintInDestructor() invoked Catched const char* exception: BANG!</code> </pre> <br><h2 id="kogda-ochen-ochen-hochetsya-vybrosit-srazu-neskolko-isklyucheniy">  When you really, really want to throw out a few exceptions </h2><br><p>  <em>std :: uncaught_exceptions ()</em> avoids calling <em>std :: terminate ()</em> , but does not help correctly handle multiple exceptions.  Ideally, I would like to have a mechanism that allows you to save all the exceptions thrown, and then process them in one place. </p><br><blockquote>  I want to remind once again that the mechanism proposed by me below serves only to demonstrate the concept and is not recommended for use in a real industrial code. </blockquote><p>  The essence of the idea is to catch exceptions and store them in a container, and then one by one get and process.  In order to save exception objects, in C ++ there is a special type of <em>std :: exception_ptr</em> .  The type structure in the Standard is not disclosed, but it is said that this is essentially a <em>shared_ptr</em> on the exception object. </p><br><p>  How then to process these exceptions?  For this, there is a function <em>std :: rethrow_exception ()</em> , which accepts a pointer <em>std :: exception_ptr</em> and throws the corresponding exception.  We only need to catch it with the corresponding catch-section and process it, after which we can proceed to the next exception object. </p><br><pre> <code class="plaintext hljs">using exceptions_queue = std::stack&lt;std::exception_ptr&gt;; // Get exceptions queue for current thread exceptions_queue&amp; get_queue() { thread_local exceptions_queue queue_; return queue_; } // Invoke functor and save exception in queue void safe_invoke(std::function&lt;void()&gt; f) noexcept { try { f(); } catch (...) { get_queue().push(std::current_exception()); } } class ThrowInDestructor { public: ~ThrowInDestructor() noexcept { std::cerr &lt;&lt; "~ThrowInDestructor() invoked\n"; safe_invoke([]() { throw_int_func(); }); } private: PrintInDestructor member_; }; int main(int, char**) { safe_invoke([]() { ThrowInDestructor bad; throw "BANG!"; }); auto&amp; q = get_queue(); while (!q.empty()) { try { std::exception_ptr ex = q.top(); q.pop(); if (ex != nullptr) { std::rethrow_exception(ex); } } catch (int i) { std::cerr &lt;&lt; "Catched int exception: " &lt;&lt; i &lt;&lt; "\n"; } catch (const char* s) { std::cerr &lt;&lt; "Catched const char* exception: " &lt;&lt; s &lt;&lt; "\n"; } catch (...) { std::cerr &lt;&lt; "Catched unknown exception\n"; } } return 0; }</code> </pre> <br><p>  Result: </p><br><pre> <code class="plaintext hljs">~ThrowInDestructor() invoked throw_int_func() invoked ~PrintInDestructor() invoked Catched const char* exception: BANG! Catched int exception: 1</code> </pre> <br><p>  In the example above, the stack is used to save objects of exceptions, however, exception handling will be performed according to the FIFO principle (that is, logically this is the queue ‚Äî the exception that was thrown first will be the first to be processed). </p><br><h2 id="vyvody">  findings </h2><br><p>  Throwing exceptions in the destructors of objects is indeed a bad idea, and in any new code I strongly recommend not to do this by declaring destructors <em>noexcept</em> .  However, with the support and debugging of legacy code, there may be a need to correctly handle exceptions thrown from destructors, including during stack promotion, and modern C ++ provides us with mechanisms for this.  I hope the ideas presented in this article will help you on this difficult path. </p><br><h2 id="ssylki">  Links </h2><br><p>  <a href="https://github.com/igor-semenov/code_samples/tree/master/destructive_exceptions">Repository with examples from the article</a> </p></div><p>Source: <a href="https://habr.com/ru/post/433944/">https://habr.com/ru/post/433944/</a></p>
<section class="more-articles-navigation-panel js-more-articles-navigation-panel">
<h4>More articles:</h4>
<nav class="list-of-articles-container js-list-of-articles-container"><ul class="list-of-pages js-list-of-pages">
<li><a href="../433932/index.html">We shoot in the foot, processing the input data</a></li>
<li><a href="../433934/index.html">SAFe or Scaled Agile Framework</a></li>
<li><a href="../433936/index.html">Looking for a hi-tech gift for a child? Think of a playground, not an arena</a></li>
<li><a href="../433938/index.html">How Yandex and Google sum up the year</a></li>
<li><a href="../433940/index.html">How much does Review in AppStore cost</a></li>
<li><a href="../433946/index.html">Crib for artificial intelligence - throw away too much, teach the main thing. Technique processing training sequences</a></li>
<li><a href="../433948/index.html">How to make payment for services more convenient: the experience of an IaaS provider</a></li>
<li><a href="../433952/index.html">10 reasons to choose a solution for SAP HANA from HPE. Part 2</a></li>
<li><a href="../433954/index.html">Eight audio technologies and audio gadgets that will get into the TECnology hall of fame in 2019</a></li>
<li><a href="../433956/index.html">Modders have attracted AI to improve textures in games</a></li>
</ul></nav>
</section><br />
<a href="../../allArticles.html"><strong>All Articles</strong></a>
<script src="../../js/main.js"></script>

<!-- Yandex.Metrika counter -->
<script type="text/javascript" >
  (function (d, w, c) {
      (w[c] = w[c] || []).push(function() {
          try {
              w.yaCounter52496797 = new Ya.Metrika({
                  id:52496797,
                  clickmap:true,
                  trackLinks:true,
                  accurateTrackBounce:true,
                  webvisor:true
              });
          } catch(e) { }
      });

      var n = d.getElementsByTagName("script")[0],
          s = d.createElement("script"),
          f = function () { n.parentNode.insertBefore(s, n); };
      s.type = "text/javascript";
      s.async = true;
      s.src = "https://mc.yandex.ru/metrika/watch.js";

      if (w.opera == "[object Opera]") {
          d.addEventListener("DOMContentLoaded", f, false);
      } else { f(); }
  })(document, window, "yandex_metrika_callbacks");
</script>
<noscript><div><img src="https://mc.yandex.ru/watch/52496797" style="position:absolute; left:-9999px;" alt="" /></div></noscript>

<!-- Google Analytics -->
  <script>
    window.ga = function () { ga.q.push(arguments) }; ga.q = []; ga.l = +new Date;
    ga('create', 'UA-134931760-1', 'auto'); ga('send', 'pageview')
  </script>
  <script src="https://www.google-analytics.com/analytics.js" async defer></script>

</section>

  <footer class="page-footer">
    <div class="page-footer-legal-info-container page-footer-element">
      <p>
        Weekly-Geekly | <span class="page-footer-legal-info-year js-page-footer-legal-info-year">2019</span>
      </p>
    </div>
    <div class="page-footer-counters-container page-footer-element">
      <a class="page-footer-counter-clustrmap" href='#'  title='Visit tracker'><img src='https://clustrmaps.com/map_v2.png?cl=698e5a&w=271&t=t&d=6iCFw7uJz0zcOaoxz5k5PcLCJUzv2WG8G5V8M3U6Rc4&co=3a3a3a&ct=ffffff'/></a>
    </div>
  </footer>
</body>

</html>