<!doctype html>
<html class="no-js" lang="en">

<head>
  <!-- Global site tag (gtag.js) - Google Analytics -->
  <script async src="https://www.googletagmanager.com/gtag/js?id=UA-134931760-1"></script>
  <script>
    window.dataLayer = window.dataLayer || [];
    function gtag(){dataLayer.push(arguments);}
    gtag('js', new Date());

    gtag('config', 'UA-134931760-1');
  </script>

  <meta charset="utf-8">
  <meta http-equiv="x-ua-compatible" content="ie=edge">
  <title>Repeated generation of exceptions</title>
  <link rel="icon" type="image/x-icon" href="/favicon.ico" />
  <meta name="description" content="Exception handling has appeared in mainstream programming languages ‚Äã‚Äãfor more than three decades ago, but today you can still find developers who are...">
  <meta name="viewport" content="width=device-width, initial-scale=1, shrink-to-fit=no">

  <link rel="stylesheet" href="../../css/main.css">

  <script src="https://cdnjs.cloudflare.com/ajax/libs/jquery/3.3.1/jquery.min.js"></script>
  <script>window.jQuery || document.write('<script src="../../js/vendors/jquery-3.3.1.min.js"><\/script>')</script>

  <script async src="//pagead2.googlesyndication.com/pagead/js/adsbygoogle.js"></script>
  <script>
       (adsbygoogle = window.adsbygoogle || []).push({
            google_ad_client: "ca-pub-6974184241884155",
            enable_page_level_ads: true
       });
  </script>
</head>

<body>
  <!--[if lte IE 9]>
    <p class="browserupgrade">You are using an <strong>outdated</strong> browser. Please <a href="https://browsehappy.com/">upgrade your browser</a> to improve your experience and security.</p>
  <![endif]-->
  <header class="page-header js-page-header">
    <a class="page-header-logo-container" href="https://weekly-geekly.github.io/index.html"></a>
    <div class="page-header-text">Geekly Articles each Day</div>
  </header>
  <nav class="page-headings-container js-page-headings-container"></nav>
  <div class="tools-bar js-tools-bar">
    <!-- <a href="../../search.html" title="Search">üîé</a> -->
    <a class="js-list-of-headings-button" data-state="closed" href="#" title="Headings">üìú</a>
    <a class="js-go-to-top-button" href="#" title="Go to Top">‚¨ÜÔ∏è</a>
    <a class="js-go-to-bottom-button" href="#" title="Go to Bottom">‚¨áÔ∏è</a>
  </div>
  <a href="http://bit.ly/donateToWeeklyGeekly" class="donate-btn">DONATE</a>
  <section class="page js-page"><h1>Repeated generation of exceptions</h1><div class="post__text post__text-html js-mediator-article">  Exception handling has appeared in mainstream programming languages ‚Äã‚Äãfor more than three decades ago, but today you can still find developers who are afraid to use them.  Some believe that the generation of exceptions in the designer will damage their fragile karma and they will be overtaken by a punishment in the form of supporting a code of twenty years ago written by a herd of insane Indians.  Some are still stuck in the era of the C language and even in C # they intensively use return codes in the form of magic numbers or even strings, believing that cowards invented exceptions, and real samurai can do without them.  (Although we all know that the real samurai follow the <a href="http://sergeyteplyakov.blogspot.com/2011/09/blog-post_13.html">‚ÄúSamurai principle‚Äù</a> and do not use any return codes). <br><br>  Additional complexity is added by specific platforms and programming languages.  Today at the C # developer's interview, when it comes to handling exceptions, the question will surely be heard: ‚ÄúWhat is the difference between throwing exceptions using <b>throw</b> constructs <b>;</b>  and <b>throw ex;</b>  ?  And although this is a terrible button accordion and most developers have long known the correct answer to this question, in the real code it‚Äôs very easy to meet the ‚Äúnon-kosher‚Äù version. <br><br>  A feature of the .NET platform is that it does not exist (or rather, as we will soon see - did not exist) a way to catch an exception in one place and then generate it in another.  If the developer of a business application or library faced this problem, then it was solved in a very simple way: the original exception was wrapped in another object as a nested exception and a new exception was forwarded. 
      <br>
        <script async src="//pagead2.googlesyndication.com/pagead/js/adsbygoogle.js"></script>
        <ins class="adsbygoogle"
          style="display:block; text-align:center;"
          data-ad-layout="in-article"
          data-ad-format="fluid"
          data-ad-client="ca-pub-6974184241884155"
          data-ad-slot="8945601208"></ins>
        <script>
          (adsbygoogle = window.adsbygoogle || []).push({});
        </script>
      <br>
    <a name="habracut"></a><br><br>  Let's look at this example.  Suppose we have a custom exception class called <b>CustomException</b> , as well as a simple class <b>SampleClass</b> , whose constructor throws this exception. <br><br><pre><code class="hljs pgsql">//   ,  ,   <span class="hljs-keyword"><span class="hljs-keyword">class</span></span> CustomException : <span class="hljs-keyword"><span class="hljs-keyword">Exception</span></span> { } <span class="hljs-keyword"><span class="hljs-keyword">class</span></span> SampleClass { //   , //     ,    <span class="hljs-built_in"><span class="hljs-built_in">public</span></span> SampleClass() { throw <span class="hljs-built_in"><span class="hljs-built_in">new</span></span> CustomException(); } }</code> </pre> <br><br>  Now let's create an object of this class using the generic method, and also make a singleton of this class: <br><br><pre> <code class="hljs pgsql">//   ,    <span class="hljs-built_in"><span class="hljs-built_in">public</span></span> static T CreateInstance&lt;T&gt;() <span class="hljs-keyword"><span class="hljs-keyword">where</span></span> T : <span class="hljs-built_in"><span class="hljs-built_in">new</span></span>() { <span class="hljs-keyword"><span class="hljs-keyword">return</span></span> <span class="hljs-built_in"><span class="hljs-built_in">new</span></span> T(); } //    <span class="hljs-keyword"><span class="hljs-keyword">class</span></span> SampleClassSingleton { private static SampleClass _instance = <span class="hljs-built_in"><span class="hljs-built_in">new</span></span> SampleClass(); static SampleClassSingleton() { } <span class="hljs-built_in"><span class="hljs-built_in">public</span></span> static SampleClass Instance { <span class="hljs-keyword"><span class="hljs-keyword">get</span></span> { <span class="hljs-keyword"><span class="hljs-keyword">return</span></span> _instance; } } }</code> </pre><br><br>  The question is what kind of <b>catch block</b> will be executed when calling the <b>CreateInstance &lt;</b> <b>SampleClass&gt; ()</b> method or when accessing <b>SampleClassSingleton.</b>  <b>Instnace</b> ? <br><br><pre> <code class="hljs coffeescript"><span class="hljs-keyword"><span class="hljs-keyword">try</span></span> { CreateInstance&lt;SampleClass&gt;(); <span class="hljs-regexp"><span class="hljs-regexp">//</span></span>  var instance = SampleClassSingleton.Instance; } <span class="hljs-keyword"><span class="hljs-keyword">catch</span></span> (CustomException e) { Console.WriteLine(e); } <span class="hljs-keyword"><span class="hljs-keyword">catch</span></span> (Exception e) { Console.WriteLine(e); }</code> </pre><br><br>  I don‚Äôt think that this code will be a great revelation for someone, but in both cases the ‚Äúexpected‚Äù <b>catch block (CustomException e)</b> will not be executed, the <b>catch block (Exception e)</b> will be executed instead. <br><br>  In the first case (that is, when using the generic <b>CreateInstance</b> method), in fact, the default constructor is not called directly, instead it uses <b>Activator.CreateInstance</b> , which wraps the original exception in a <b>TargetInvocationException</b> .  That is why the <b>catch (Exception e)</b> block is triggered, since a <b>TargetInvocationException</b> doesn‚Äôt suit our first exception block. <br><br>  <b><font color="#526e66">A WARNING</font></b> <b><br></b>  <font color="#526e66">Do not write only e.Message in the logs, because when your production server lies down from this information you will be neither cold nor hot, since the most valuable information may be hidden in one of the nested exceptions.</font>  <font color="#526e66">Even as part of the .Net Framework, there are many places that wrap the original exception and throw it as a nested one, not to mention custom code that can wrap the exception you need in a dozen nested ones.</font> <br><br>  When using singleton, the situation is similar: since the initialization of the <b>_instance</b> field occurs in the static constructor, any exceptions that occur during its execution make the type "invalid."  As a result, all subsequent calls to this type result in a <b>TypeLoadException</b> exception with a corresponding nested exception. <br><br>  <b><font color="#526e66">NOTE</font></b> <font color="#526e66">For more information on what an empty static constructor is needed for and what problems its absence can cause, see <a href="http://sergeyteplyakov.blogspot.com/2011/08/blog-post.html">About singletons and static constructors</a> <font color="#526e66">.</font></font> <br><br>  Behavior in both cases is well documented and well-known, so if once it could be considered a bug, now this is already a feature.  But we cannot correct this situation, unfortunately.  Even if we catch the exception in the <b>CreateInstance</b> method and try to forward the nested exception, we will lose the call stack, which will make the resulting exception much less useful: <br><br><pre> <code class="hljs cs"><span class="hljs-keyword"><span class="hljs-keyword">public</span></span> <span class="hljs-keyword"><span class="hljs-keyword">static</span></span> T CreateInstance&lt;T&gt;() <span class="hljs-keyword"><span class="hljs-keyword">where</span></span> T : <span class="hljs-keyword"><span class="hljs-keyword">new</span></span>() { <span class="hljs-keyword"><span class="hljs-keyword">try</span></span> { <span class="hljs-keyword"><span class="hljs-keyword">return</span></span> <span class="hljs-keyword"><span class="hljs-keyword">new</span></span> T(); } <span class="hljs-keyword"><span class="hljs-keyword">catch</span></span> (TargetInvocationException e) { <span class="hljs-comment"><span class="hljs-comment">//    ,    ,   ! throw e.InnerException; } }</span></span></code> </pre><br><br>  A similar problem awaits us if we try to save an exception when creating an instance of _ <b>instance</b> and will forward it when accessing the <b>Instance</b> property.  (Yes, deferred initialization will solve this particular problem, but now this is not the point). <br><br>  However, a class appeared in the .Net Framework 4.5 that can help solve this problem.  This is the <b>ExceptionDispatchInfo</b> class that can save the original exception and then re-forward it without losing information about the call stack.  Of course, the basic meaning of its use is not related to the ‚Äústraightening‚Äù of static constructors or the <b>Activator.CreateInstance</b> method.  Its main task is to address issues of asynchrony and multithreading, when an exception occurs in one stream, and is forwarded in another. <br><br>  Let's look at the following code: <br><br><pre> <code class="hljs coffeescript">Task&lt;int&gt; task = Task&lt;int&gt;.Factory.StartNew(<span class="hljs-function"><span class="hljs-params"><span class="hljs-function"><span class="hljs-params">()</span></span></span><span class="hljs-function"> =&gt;</span></span> { <span class="hljs-keyword"><span class="hljs-keyword">throw</span></span> <span class="hljs-keyword"><span class="hljs-keyword">new</span></span> CustomException(); }); <span class="hljs-keyword"><span class="hljs-keyword">try</span></span> { int result = task.Result; } <span class="hljs-keyword"><span class="hljs-keyword">catch</span></span> (CustomException e) { <span class="hljs-regexp"><span class="hljs-regexp">//</span></span> ,      :( Console.WriteLine(<span class="hljs-string"><span class="hljs-string">"CustomException caught: "</span></span> + e); } <span class="hljs-keyword"><span class="hljs-keyword">catch</span></span> (AggregateException e) { <span class="hljs-regexp"><span class="hljs-regexp">//</span></span>      ! var inner = e.GetBaseException(); Console.WriteLine(<span class="hljs-string"><span class="hljs-string">"Aggregate excpetion caught: "</span></span> + inner); }</code> </pre><br><br>  If the ‚Äútask‚Äù falls with an exception, then the original exception (in our case, <b>CustomException</b> ) will be wrapped in an <b>AggregateException</b> .  There are several reasons for this behavior: first, although the task is by its nature a shell over some long-term asynchronous operation with a single result, in some cases the result of one task may be based on the results of parallel execution of several tasks.  For example, we can combine several tasks into one using <b>Task</b> <b>.</b>  <b>WaitAll</b> or we can link several tasks with continuations.  The second reason for this behavior is the impossibility of forwarding the original exception without distorting its call stack. <br><br>  However, after the appearance of new features in working with asynchrony in C # 5.0, priorities have changed somewhat.  One of the main features of the <b>await</b> and <b>async</b> keywords is the simplicity of converting synchronous code into asynchronous, but in addition to ‚Äústraightening‚Äù the flow of execution (which even in the case of application of tasks leaves much to be desired), the problem of exception handling must also be solved.  Therefore, when getting the results of a task using the <b>await</b> keyword, the original <b>AggregateException is</b> expanded and the original exception is forwarded: <br><br><pre> <code class="hljs cs"><span class="hljs-function"><span class="hljs-keyword"><span class="hljs-function"><span class="hljs-keyword">public</span></span></span><span class="hljs-function"> </span><span class="hljs-keyword"><span class="hljs-function"><span class="hljs-keyword">static</span></span></span><span class="hljs-function"> </span><span class="hljs-keyword"><span class="hljs-function"><span class="hljs-keyword">async</span></span></span><span class="hljs-function"> </span><span class="hljs-keyword"><span class="hljs-function"><span class="hljs-keyword">void</span></span></span><span class="hljs-function"> </span><span class="hljs-title"><span class="hljs-function"><span class="hljs-title">SimpleTask</span></span></span><span class="hljs-function">(</span><span class="hljs-params"></span><span class="hljs-function"><span class="hljs-params"></span>)</span></span> { Task&lt;<span class="hljs-keyword"><span class="hljs-keyword">int</span></span>&gt; task = Task&lt;<span class="hljs-keyword"><span class="hljs-keyword">int</span></span>&gt;.Factory.StartNew(() =&gt; { <span class="hljs-keyword"><span class="hljs-keyword">throw</span></span> <span class="hljs-keyword"><span class="hljs-keyword">new</span></span> CustomException(); }); <span class="hljs-keyword"><span class="hljs-keyword">try</span></span> { <span class="hljs-comment"><span class="hljs-comment">// await ¬´¬ª      //    ,   AggregateExcpetion! int result = await task; } catch (CustomException e) { //    ,       Console.WriteLine("CustomException caught: " + e); } }</span></span></code> </pre><br><br>  <font color="#526e66"><b>NOTE</b></font> <font color="#526e66"><br></font>  <font color="#526e66">If you are not familiar with such features of the C # 5.0 language as <b>async</b> and <b>await</b> , then you can fill this gap with the help of the article:</font> <a href="http://sergeyteplyakov.blogspot.com/2010/12/c-5.html"><font color="#526e66">Asynchronous operations in C # 5</font></a> <br><br>  As already mentioned, this behavior is implemented using the new <b>ExceptionDispatchInfo</b> class, which allows you to save the original exception and forward it later, perhaps even in a new thread.  Moreover, it is implemented so simply that it is not difficult for us to do it on our own. <br><br>  To begin with, let's create a class for the T <b>ask</b> <b>&lt;</b> <b>T</b> <b>&gt;</b> class with the <b>GetResult</b> extension <b>method</b> , which will be very similar to the <b>Result</b> property, but will ‚Äústraighten‚Äù <b>AggregateExcpetion</b> and forward an nested exception without losing the call stack. <br><br>  <font color="#526e66"><b>NOTE</b></font> <font color="#526e66"><br></font>  <font color="#526e66">This behavior has already been implemented as part of .Net Framework 4.5 using <b>Task</b> <b>&lt;</b> <b>T</b> <b>&gt;.</b></font>  <font color="#526e66"><b>GetAwaiter</b> <b>().</b></font>  <font color="#526e66"><b>GetResult</b> <b>()</b> , but let's forget about it and do the same thing yourself.</font> <br><br>  Using the <b>ExceptionDispatchInfo</b> class is quite simple: to do this, it is enough to capture the exception in one place using the static method <b>Capture</b> , and then forward the exception in another place (and possibly even in another thread) using the <b>Throw</b> method. <br><br><pre> <code class="hljs kotlin">static <span class="hljs-class"><span class="hljs-keyword"><span class="hljs-class"><span class="hljs-keyword">class</span></span></span><span class="hljs-class"> </span><span class="hljs-title"><span class="hljs-class"><span class="hljs-title">TaskExtensions</span></span></span><span class="hljs-class"> </span></span>{ <span class="hljs-keyword"><span class="hljs-keyword">public</span></span> static T GetResult&lt;T&gt;(<span class="hljs-keyword"><span class="hljs-keyword">this</span></span> Task&lt;T&gt; task) { <span class="hljs-keyword"><span class="hljs-keyword">try</span></span> { T result = task.Result; <span class="hljs-keyword"><span class="hljs-keyword">return</span></span> result; } <span class="hljs-keyword"><span class="hljs-keyword">catch</span></span> (AggregateException e) { ExceptionDispatchInfo di = ExceptionDispatchInfo.Capture(e.InnerException); di.Throw(); <span class="hljs-keyword"><span class="hljs-keyword">return</span></span> <span class="hljs-keyword"><span class="hljs-keyword">default</span></span>(T); } } }</code> </pre><br><br>  Now, if we change the previous code snippet and replace the <b>task</b> <b>.</b>  <b>Result</b> to call the <b>Task</b> method <b>.</b>  <b>GetResult</b> , then we will be able to intercept a specific exception type instead of an <b>AggregateException</b> exception. <br><br><pre> <code class="hljs cs">Task&lt;<span class="hljs-keyword"><span class="hljs-keyword">int</span></span>&gt; task = Task&lt;<span class="hljs-keyword"><span class="hljs-keyword">int</span></span>&gt;.Factory.StartNew(() =&gt; { <span class="hljs-keyword"><span class="hljs-keyword">throw</span></span> <span class="hljs-keyword"><span class="hljs-keyword">new</span></span> CustomException(); }); <span class="hljs-keyword"><span class="hljs-keyword">try</span></span> { <span class="hljs-keyword"><span class="hljs-keyword">int</span></span> result = task.GetResult(); } <span class="hljs-keyword"><span class="hljs-keyword">catch</span></span> (CustomException e) { <span class="hljs-comment"><span class="hljs-comment">//     CustomException,   AggregateException Console.WriteLine("CustomException caught: " + e); }</span></span></code> </pre><br><br>  Similarly, you can change our <b>CreateInstance</b> method, which will catch the <b>TargetInfocationException</b> exception and throw a nested exception: <br><br><pre> <code class="hljs cs"><span class="hljs-keyword"><span class="hljs-keyword">public</span></span> <span class="hljs-keyword"><span class="hljs-keyword">static</span></span> T CreateInstance&lt;T&gt;() <span class="hljs-keyword"><span class="hljs-keyword">where</span></span> T : <span class="hljs-keyword"><span class="hljs-keyword">new</span></span>() { <span class="hljs-keyword"><span class="hljs-keyword">try</span></span> { <span class="hljs-keyword"><span class="hljs-keyword">var</span></span> t = <span class="hljs-keyword"><span class="hljs-keyword">new</span></span> T(); <span class="hljs-keyword"><span class="hljs-keyword">return</span></span> t; } <span class="hljs-keyword"><span class="hljs-keyword">catch</span></span> (TargetInvocationException e) { <span class="hljs-comment"><span class="hljs-comment">//     ExceptionDispatchInfo ExceptionDispatchInfo di = ExceptionDispatchInfo.Capture(e.InnerException); //        di.Throw(); //   ,  di.Throws()   ,  //        ,     //   return default(T); } }</span></span></code> </pre><br><br>  Now, when we try to call this method from the <b>Main</b> function, we will get a sensible exception with the normal execution stack: <br><br> <code>ConsoleApplication1.CustomException: Exception of type 'ConsoleApplication1.CustomException' was thrown.&lt;br&gt;at ConsoleApplication1.SampleClass..ctor() in &lt;br&gt;c:\Projects\ConsoleApplication1\ConsoleApplication1\Program.cs:line 19&lt;br&gt; <font><b>--- End of stack trace from previous location where exception was thrown ---&lt;br&gt;</b> at System.Runtime.ExceptionServices.ExceptionDispatchInfo.Throw()&lt;br&gt;at ConsoleApplication1.Program.CreateInstance[T]() in c&lt;br&gt;\Projects\ConsoleApplication1\ConsoleApplication1\Program.cs:&lt;br&gt;line 50&lt;br&gt;at ConsoleApplication1.Program.Main(String[] args) in c:\ \Projects\ConsoleApplication1\ConsoleApplication1\Program.cs:line 63</font> <br></code> <br><br>  The singleton class can be implemented in a similar way. <br><br>  The <b>ExceptionDispatchInfo</b> class is unlikely to have a killer feature of the .Net Framework version, but with the onset of the asynchrony era, it will definitely have a decent scope.  So, for example, it is already used in the library of reactive extensions to implement the <b>await</b> pattern (this implementation is available only in the experimental release) and can be used by anyone who wants to implement this pattern on their own. </div><p>Source: <a href="https://habr.com/ru/post/131811/">https://habr.com/ru/post/131811/</a></p>
<section class="more-articles-navigation-panel js-more-articles-navigation-panel">
<h4>More articles:</h4>
<nav class="list-of-articles-container js-list-of-articles-container"><ul class="list-of-pages js-list-of-pages">
<li><a href="../131805/index.html">UkrYama - fight with the pits in Ukraine</a></li>
<li><a href="../131806/index.html">Tenzor company has announced a programming contest, the prize is a scholarship from them for the whole academic year.</a></li>
<li><a href="../131808/index.html">Google learned to index Facebook comments</a></li>
<li><a href="../13181/index.html">Apple's design success secret ...</a></li>
<li><a href="../131810/index.html">The company "Penguin Software" has completed the development of a prototype of the national software platform</a></li>
<li><a href="../131813/index.html">Duqu: 0day + installer</a></li>
<li><a href="../131814/index.html">IOS 5.0.1 released for developers</a></li>
<li><a href="../131815/index.html">Making Step Sequencer with Max4Live</a></li>
<li><a href="../131818/index.html">Pros and Cons Percentage Chart on Canvas</a></li>
<li><a href="../13182/index.html">Agent for writing topics</a></li>
</ul></nav>
</section><br />
<a href="../../allArticles.html"><strong>All Articles</strong></a>
<script src="../../js/main.js"></script>

<!-- Yandex.Metrika counter -->
<script type="text/javascript" >
  (function (d, w, c) {
      (w[c] = w[c] || []).push(function() {
          try {
              w.yaCounter52496797 = new Ya.Metrika({
                  id:52496797,
                  clickmap:true,
                  trackLinks:true,
                  accurateTrackBounce:true,
                  webvisor:true
              });
          } catch(e) { }
      });

      var n = d.getElementsByTagName("script")[0],
          s = d.createElement("script"),
          f = function () { n.parentNode.insertBefore(s, n); };
      s.type = "text/javascript";
      s.async = true;
      s.src = "https://mc.yandex.ru/metrika/watch.js";

      if (w.opera == "[object Opera]") {
          d.addEventListener("DOMContentLoaded", f, false);
      } else { f(); }
  })(document, window, "yandex_metrika_callbacks");
</script>
<noscript><div><img src="https://mc.yandex.ru/watch/52496797" style="position:absolute; left:-9999px;" alt="" /></div></noscript>

<!-- Google Analytics -->
  <script>
    window.ga = function () { ga.q.push(arguments) }; ga.q = []; ga.l = +new Date;
    ga('create', 'UA-134931760-1', 'auto'); ga('send', 'pageview')
  </script>
  <script src="https://www.google-analytics.com/analytics.js" async defer></script>

</section>

  <footer class="page-footer">
    <div class="page-footer-legal-info-container page-footer-element">
      <p>
        Weekly-Geekly | <span class="page-footer-legal-info-year js-page-footer-legal-info-year">2019</span>
      </p>
    </div>
    <div class="page-footer-counters-container page-footer-element">
      <a class="page-footer-counter-clustrmap" href='#'  title='Visit tracker'><img src='https://clustrmaps.com/map_v2.png?cl=698e5a&w=271&t=t&d=6iCFw7uJz0zcOaoxz5k5PcLCJUzv2WG8G5V8M3U6Rc4&co=3a3a3a&ct=ffffff'/></a>
    </div>
  </footer>
</body>

</html>